<?xml version="1.0" ?>
<robot name="robot">
  <link name="part_2_1">
    <inertial>
      <origin xyz="0.0015091554 -0.083174522 0.03214416" rpy="0 0 0"/>
      <mass value="1.0"/>
      <inertia ixx="0.001" ixy="0" ixz="0" iyy="0.001" iyz="0" izz="0.001"/>
    </inertial>
    <visual>
      <origin xyz="0.0015091554 -0.083174522 0.03214416" rpy="0 0 0"/>
      <geometry>
        <mesh filename="meshes/part_2_1.stl"/>
      </geometry>
    </visual>
    <collision>
      <origin xyz="0.0015091554 -0.083174522 0.03214416" rpy="0 0 0"/>
      <geometry>
        <mesh filename="meshes/part_2_1.stl"/>
      </geometry>
    </collision>
  </link>
  <joint name="revolute_1" type="revolute">
    <origin xyz="-0.04976857 -0.083174522 0.07368213" rpy="-1.5707963 0 0"/>
    <parent link="part_2_1"/>
    <child link="part_1_1"/>
    <axis xyz="0 0 1"/>
    <limit effort="100" velocity="3.14159" lower="-3.14159" upper="3.14159"/>
  </joint>
  <link name="part_1_1">
    <inertial>
      <origin xyz="-0.062523908 0.014552589 0" rpy="1.5707963 0 2.208934"/>
      <mass value="1.0"/>
      <inertia ixx="0.001" ixy="0" ixz="0" iyy="0.001" iyz="0" izz="0.001"/>
    </inertial>
    <visual>
      <origin xyz="-0.062523908 0.014552589 0" rpy="1.5707963 0 2.208934"/>
      <geometry>
        <mesh filename="meshes/part_1_1.stl"/>
      </geometry>
    </visual>
    <collision>
      <origin xyz="-0.062523908 0.014552589 0" rpy="1.5707963 0 2.208934"/>
      <geometry>
        <mesh filename="meshes/part_1_1.stl"/>
      </geometry>
    </collision>
  </link>
</robot>
