<?xml version="1.0" ?>
<robot name="robot">
  <link name="part_1_1">
    <inertial>
      <origin xyz="0 0 0" rpy="0 0 0"/>
      <mass value="0.1042"/>
      <inertia ixx="9.7753835e-05" ixy="0" ixz="0" iyy="2.5181667e-05" iyz="0" izz="0.00011598883"/>
    </inertial>
    <visual>
      <origin xyz="0 0 0" rpy="0 0 0"/>
      <geometry>
        <mesh filename="meshes/part_1_1.stl"/>
      </geometry>
    </visual>
    <collision>
      <origin xyz="0 0 0" rpy="0 0 0"/>
      <geometry>
        <mesh filename="meshes/part_1_1.stl"/>
      </geometry>
    </collision>
  </link>
  <joint name="revolute_1" type="continuous">
    <origin xyz="-0.025 -0.0521 0" rpy="1.5707963 0 1.5707963"/>
    <parent link="part_1_1"/>
    <child link="part_3_1"/>
    <axis xyz="0 0 1"/>
  </joint>
  <link name="part_3_1">
    <inertial>
      <origin xyz="0 0 -0.00705" rpy="0 0 0"/>
      <mass value="0.019490441"/>
      <inertia ixx="2.271952e-06" ixy="0" ixz="0" iyy="2.271952e-06" iyz="0" izz="3.8980882e-06"/>
    </inertial>
    <visual>
      <origin xyz="0.071338835 -0.02469685 0.0301" rpy="-1.9040736 -1.5707963 0"/>
      <geometry>
        <mesh filename="meshes/part_3_1.stl"/>
      </geometry>
    </visual>
    <collision>
      <origin xyz="0.071338835 -0.02469685 0.0301" rpy="-1.9040736 -1.5707963 0"/>
      <geometry>
        <mesh filename="meshes/part_3_1.stl"/>
      </geometry>
    </collision>
  </link>
  <joint name="revolute_2" type="continuous">
    <origin xyz="0.025 -0.0521 0" rpy="-1.5707963 0 1.5707963"/>
    <parent link="part_1_1"/>
    <child link="part_2_1"/>
    <axis xyz="0 0 1"/>
  </joint>
  <link name="part_2_1">
    <inertial>
      <origin xyz="0 0 -0.00705" rpy="0 0 0"/>
      <mass value="0.019490441"/>
      <inertia ixx="2.271952e-06" ixy="0" ixz="0" iyy="2.271952e-06" iyz="0" izz="3.8980882e-06"/>
    </inertial>
    <visual>
      <origin xyz="0.075492806 0 0" rpy="1.5707963 1.5707963 0"/>
      <geometry>
        <mesh filename="meshes/part_2_1.stl"/>
      </geometry>
    </visual>
    <collision>
      <origin xyz="0.075492806 0 0" rpy="1.5707963 1.5707963 0"/>
      <geometry>
        <mesh filename="meshes/part_2_1.stl"/>
      </geometry>
    </collision>
  </link>
  <joint name="revolute_3" type="continuous">
    <origin xyz="0.025 0.0521 0" rpy="-1.5707963 0 1.5707963"/>
    <parent link="part_1_1"/>
    <child link="part_4_1"/>
    <axis xyz="0 0 1"/>
  </joint>
  <link name="part_4_1">
    <inertial>
      <origin xyz="0 0 -0.00705" rpy="0 0 0"/>
      <mass value="0.019490441"/>
      <inertia ixx="2.271952e-06" ixy="0" ixz="0" iyy="2.271952e-06" iyz="0" izz="3.8980882e-06"/>
    </inertial>
    <visual>
      <origin xyz="-0.085707194 0 0" rpy="1.5707963 1.5707963 0"/>
      <geometry>
        <mesh filename="meshes/part_4_1.stl"/>
      </geometry>
    </visual>
    <collision>
      <origin xyz="-0.085707194 0 0" rpy="1.5707963 1.5707963 0"/>
      <geometry>
        <mesh filename="meshes/part_4_1.stl"/>
      </geometry>
    </collision>
  </link>
  <joint name="revolute_4" type="continuous">
    <origin xyz="-0.025 0.0521 0" rpy="1.5707963 0 1.5707963"/>
    <parent link="part_1_1"/>
    <child link="part_5_1"/>
    <axis xyz="0 0 1"/>
  </joint>
  <link name="part_5_1">
    <inertial>
      <origin xyz="0 0 -0.00705" rpy="0 0 0"/>
      <mass value="0.019490441"/>
      <inertia ixx="2.271952e-06" ixy="0" ixz="0" iyy="2.271952e-06" iyz="0" izz="3.8980882e-06"/>
    </inertial>
    <visual>
      <origin xyz="-0.085707194 0 0.0301" rpy="-1.5707963 -1.5707963 0"/>
      <geometry>
        <mesh filename="meshes/part_5_1.stl"/>
      </geometry>
    </visual>
    <collision>
      <origin xyz="-0.085707194 0 0.0301" rpy="-1.5707963 -1.5707963 0"/>
      <geometry>
        <mesh filename="meshes/part_5_1.stl"/>
      </geometry>
    </collision>
  </link>
</robot>
